Workbook

Sheet Ausleihen
A1: Gerätenummer | B1: Mitarbeiter-ID | C1: Ausgabe am | D1: Rückgabe am
A2: G0035 | B2: 1009 | C2: 45421
A3: G0021 | B3: 1008 | C3: 45930 | D3: 45935
A4: G0024 | B4: 1005 | C4: 45743 | D4: 45868
A5: G0016 | B5: 1010 | C5: 45866
A6: G0006 | B6: 1012 | C6: 45808 | D6: 45818
A7: G0005 | B7: 1009 | C7: 45389
A8: G0009 | B8: 1011 | C8: 45850 | D8: 45853
A9: G0011 | B9: 1005 | C9: 45837 | D9: 45898
A10: G0028 | B10: 1004 | C10: 45523
A11: G0013 | B11: 1012 | C11: 45419 | D11: 45470
A12: G0024 | B12: 1008 | C12: 45375
A13: G0029 | B13: 1002 | C13: 45921 | D13: 45934
A14: G0005 | B14: 1006 | C14: 45892 | D14: 45922
A15: G0015 | B15: 1010 | C15: 45377 | D15: 45886
A16: G0005 | B16: 1012 | C16: 45599
A17: G0015 | B17: 1002 | C17: 45519
A18: G0022 | B18: 1002 | C18: 45899 | D18: 45930
A19: G0018 | B19: 1011 | C19: 45568 | D19: 45623
A20: G0035 | B20: 1003 | C20: 45417
A21: G0031 | B21: 1004 | C21: 45320
A22: G0027 | B22: 1004 | C22: 45403 | D22: 45839
A23: G0028 | B23: 1006 | C23: 45630 | D23: 45732
A24: G0030 | B24: 1012 | C24: 45792 | D24: 45905
A25: G0007 | B25: 1001 | C25: 45544 | D25: 45854
A26: G0022 | B26: 1002 | C26: 45493 | D26: 45663
A27: G0013 | B27: 1009 | C27: 45319 | D27: 45714
A28: G0028 | B28: 1003 | C28: 45595 | D28: 45630
A29: G0016 | B29: 1002 | C29: 45799 | D29: 45808
A30: G0007 | B30: 1001 | C30: 45880
A31: G0035 | B31: 1001 | C31: 45297
A32: G0016 | B32: 1003 | C32: 45330 | D32: 45817
A33: G0031 | B33: 1004 | C33: 45336
A34: G0004 | B34: 1003 | C34: 45827 | D34: 45908
A35: G0025 | B35: 1005 | C35: 45675
A36: G0030 | B36: 1005 | C36: 45261 | D36: 45559
A37: G0032 | B37: 1003 | C37: 45508 | D37: 45871
A38: G0014 | B38: 1001 | C38: 45622 | D38: 45719
A39: G0035 | B39: 1001 | C39: 45641
A40: G0004 | B40: 1001 | C40: 45880 | D40: 45881
...

Sheet Geraete
A1: Gerätenummer | B1: Gerätetyp | C1: Modell | D1: Kaufdatum | E1: Netto-Kaufpreis | F1: Standort
A2: G0001 | B2: Tablet | C2: Galaxy Tab | D2: 44937 | E2: 1342.83 | F2: Berlin
A3: G0002 | B3: Tablet | C3: Surface Go | D3: 44250 | E3: 1076.18 | F3: München
A4: G0003 | B4: Tablet | C4: iPad | D4: 45543 | E4: 1931.54 | F4: München
A5: G0004 | B5: Laptop | C5: Dell XPS | D5: 45782 | E5: 1007.88 | F5: München
A6: G0005 | B6: Drucker | C6: Canon Pixma | D6: 44503 | E6: 823.23 | F6: Berlin
A7: G0006 | B7: Smartphone | C7: Samsung S21 | D7: 45292 | E7: 1257.96 | F7: München
A8: G0007 | B8: Laptop | C8: Lenovo ThinkPad | D8: 44360 | E8: 869.09 | F8: Hamburg
A9: G0008 | B9: Beamer | C9: Epson EB | D9: 45831 | E9: 1323.76 | F9: Hamburg
A10: G0009 | B10: Laptop | C10: Dell XPS | D10: 45026 | E10: 1458.02 | F10: München
A11: G0010 | B11: Laptop | C11: Dell XPS | D11: 45239 | E11: 1786.37 | F11: München
A12: G0011 | B12: Drucker | C12: Brother HL | D12: 45909 | E12: 141.71 | F12: München
A13: G0012 | B13: Tablet | C13: Galaxy Tab | D13: 44713 | E13: 968.43 | F13: Hamburg
... A36: G0035 | B36: Beamer | C36: BenQ MW550 | D36: 45294 | E36: 644.54 | F36: Berlin

Sheet Mitarbeiter
A1: Mitarbeiter-ID | B1: Name | C1: Abteilung | D1: Standort
A2: 1001 | B2: Aleksandr Weinhage | C2: IT | D2: Berlin
A3: 1002 | B3: Eleni Hauffer | C3: IT | D3: Berlin
A4: 1003 | B4: Paul Dobes-Stiffel | C4: Produktion | D4: Hamburg
A5: 1004 | B5: Klemens Löffler | C5: Vertrieb | D5: Hamburg
A6: 1005 | B6: Alexandre Davids | C6: Vertrieb | D6: Berlin
A7: 1006 | B7: Eric Patberg B.Sc. | C7: Vertrieb | D7: Hamburg
A8: 1007 | B8: Orhan Siering MBA. | C8: IT | D8: Berlin
A9: 1008 | B9: Dipl.-Ing. Klaus-Werner Holsten B.Sc. | C9: IT | D9: Hamburg
A10: 1009 | B10: Univ.Prof. Heimo Karge | C10: Marketing | D10: Hamburg
A11: 1010 | B11: Carolin Hande | C11: IT | D11: Hamburg
A12: 1011 | B12: Auguste Davids | C12: IT | D12: Hamburg
A13: 1012 | B13: Ariane Klemt-Kaul | C13: IT | D13: München

Sheet PivotTable
A3: Anzahl von Gerätenummer | B3: Spaltenbeschriftungen
A4: Zeilenbeschriftungen | B4: Berlin | C4: Hamburg | D4: München | E4: Gesamtergebnis
A5: Beamer | B5: 7 | C5: 3 | D5: 2 | E5: 12
A6: Drucker | B6: 9 | C6: 2 | D6: 1 | E6: 12
A7: Laptop | C7: 4 | D7: 6 | E7: 10
A8: Monitor | B8: 2 | D8: 2 | E8: 4
A9: Smartphone | D9: 4 | E9: 4
A10: Tablet | C10: 2 | D10: 1 | E10: 3
A11: Gesamtergebnis | B11: 18 | C11: 11 | D11: 16 | E11: 45

Sheet Gesamt
A1: Gerätenummer | B1: Mitarbeiter-ID | C1: Ausgabe am | D1: Rückgabe am | E1: Gerätetyp | F1: Modell | G1: Kaufdatum | H1: Netto-Kaufpreis | I1: Standort | J1: Name | K1: Abteilung | L1: Standort2
A2: G0035 | B2: 1009 | C2: 45421 | E2: =VLOOKUP(A2,Geraete!A:F,2,FALSE) -> Beamer | F2: =VLOOKUP(A2,Geraete!A:F,3,FALSE) -> BenQ MW550 | G2: =VLOOKUP(A2,Geraete!A:F,4,FALSE) -> 45294 | H2: =VLOOKUP(A2,Geraete!A:F,5,FALSE) -> 644.54 | I2: =VLOOKUP(A2,Geraete!A:F,6,FALSE) -> Berlin | J2: =VLOOKUP(B2&"",Mitarbeiter!$A:$D,2,FALSE) -> Univ.Prof. Heimo Karge | K2: =VLOOKUP(B2&"",Mitarbeiter!$A:$D,3,FALSE) -> Marketing | L2: =VLOOKUP(B2&"",Mitarbeiter!$A:$D,4,FALSE) -> Hamburg
A3: G0021 | B3: 1008 | C3: 45930 | D3: 45935 | E3: =VLOOKUP(A3,Geraete!A:F,2,FALSE) -> Monitor | F3: =VLOOKUP(A3,Geraete!A:F,3,FALSE) -> Samsung Curved | G3: =VLOOKUP(A3,Geraete!A:F,4,FALSE) -> 44979 | H3: =VLOOKUP(A3,Geraete!A:F,5,FALSE) -> 1134.16 | I3: =VLOOKUP(A3,Geraete!A:F,6,FALSE) -> München | J3: =VLOOKUP(B3&"",Mitarbeiter!$A:$D,2,FALSE) -> Dipl.-Ing. Klaus-Werner Holsten B.Sc. | K3: =VLOOKUP(B3&"",Mitarbeiter!$A:$D,3,FALSE) -> IT | L3: =VLOOKUP(B3&"",Mitarbeiter!$A:$D,4,FALSE) -> Hamburg
A4: G0024 | B4: 1005 | C4: 45743 | D4: 45868 | E4: =VLOOKUP(A4,Geraete!A:F,2,FALSE) -> Monitor | F4: =VLOOKUP(A4,Geraete!A:F,3,FALSE) -> Dell UltraSharp | G4: =VLOOKUP(A4,Geraete!A:F,4,FALSE) -> 44621 | H4: =VLOOKUP(A4,Geraete!A:F,5,FALSE) -> 750.91 | I4: =VLOOKUP(A4,Geraete!A:F,6,FALSE) -> Berlin | J4: =VLOOKUP(B4&"",Mitarbeiter!$A:$D,2,FALSE) -> Alexandre Davids | K4: =VLOOKUP(B4&"",Mitarbeiter!$A:$D,3,FALSE) -> Vertrieb | L4: =VLOOKUP(B4&"",Mitarbeiter!$A:$D,4,FALSE) -> Berlin
A5: G0016 | B5: 1010 | C5: 45866 | E5: =VLOOKUP(A5,Geraete!A:F,2,FALSE) -> Drucker | F5: =VLOOKUP(A5,Geraete!A:F,3,FALSE) -> Canon Pixma | G5: =VLOOKUP(A5,Geraete!A:F,4,FALSE) -> 45015 | H5: =VLOOKUP(A5,Geraete!A:F,5,FALSE) -> 1501.06 | I5: =VLOOKUP(A5,Geraete!A:F,6,FALSE) -> Berlin | J5: =VLOOKUP(B5&"",Mitarbeiter!$A:$D,2,FALSE) -> Carolin Hande | K5: =VLOOKUP(B5&"",Mitarbeiter!$A:$D,3,FALSE) -> IT | L5: =VLOOKUP(B5&"",Mitarbeiter!$A:$D,4,FALSE) -> Hamburg
A6: G0006 | B6: 1012 | C6: 45808 | D6: 45818 | E6: =VLOOKUP(A6,Geraete!A:F,2,FALSE) -> Smartphone | F6: =VLOOKUP(A6,Geraete!A:F,3,FALSE) -> Samsung S21 | G6: =VLOOKUP(A6,Geraete!A:F,4,FALSE) -> 45292 | H6: =VLOOKUP(A6,Geraete!A:F,5,FALSE) -> 1257.96 | I6: =VLOOKUP(A6,Geraete!A:F,6,FALSE) -> München | J6: =VLOOKUP(B6&"",Mitarbeiter!$A:$D,2,FALSE) -> Ariane Klemt-Kaul | K6: =VLOOKUP(B6&"",Mitarbeiter!$A:$D,3,FALSE) -> IT | L6: =VLOOKUP(B6&"",Mitarbeiter!$A:$D,4,FALSE) -> München
A7: G0005 | B7: 1009 | C7: 45389 | E7: =VLOOKUP(A7,Geraete!A:F,2,FALSE) -> Drucker | F7: =VLOOKUP(A7,Geraete!A:F,3,FALSE) -> Canon Pixma | G7: =VLOOKUP(A7,Geraete!A:F,4,FALSE) -> 44503 | H7: =VLOOKUP(A7,Geraete!A:F,5,FALSE) -> 823.23 | I7: =VLOOKUP(A7,Geraete!A:F,6,FALSE) -> Berlin | J7: =VLOOKUP(B7&"",Mitarbeiter!$A:$D,2,FALSE) -> Univ.Prof. Heimo Karge | K7: =VLOOKUP(B7&"",Mitarbeiter!$A:$D,3,FALSE) -> Marketing | L7: =VLOOKUP(B7&"",Mitarbeiter!$A:$D,4,FALSE) -> Hamburg
A8: G0009 | B8: 1011 | C8: 45850 | D8: 45853 | E8: =VLOOKUP(A8,Geraete!A:F,2,FALSE) -> Laptop | F8: =VLOOKUP(A8,Geraete!A:F,3,FALSE) -> Dell XPS | G8: =VLOOKUP(A8,Geraete!A:F,4,FALSE) -> 45026 | H8: =VLOOKUP(A8,Geraete!A:F,5,FALSE) -> 1458.02 | I8: =VLOOKUP(A8,Geraete!A:F,6,FALSE) -> München | J8: =VLOOKUP(B8&"",Mitarbeiter!$A:$D,2,FALSE) -> Auguste Davids | K8: =VLOOKUP(B8&"",Mitarbeiter!$A:$D,3,FALSE) -> IT | L8: =VLOOKUP(B8&"",Mitarbeiter!$A:$D,4,FALSE) -> Hamburg
A9: G0011 | B9: 1005 | C9: 45837 | D9: 45898 | E9: =VLOOKUP(A9,Geraete!A:F,2,FALSE) -> Drucker | F9: =VLOOKUP(A9,Geraete!A:F,3,FALSE) -> Brother HL | G9: =VLOOKUP(A9,Geraete!A:F,4,FALSE) -> 45909 | H9: =VLOOKUP(A9,Geraete!A:F,5,FALSE) -> 141.71 | I9: =VLOOKUP(A9,Geraete!A:F,6,FALSE) -> München | J9: =VLOOKUP(B9&"",Mitarbeiter!$A:$D,2,FALSE) -> Alexandre Davids | K9: =VLOOKUP(B9&"",Mitarbeiter!$A:$D,3,FALSE) -> Vertrieb | L9: =VLOOKUP(B9&"",Mitarbeiter!$A:$D,4,FALSE) -> Berlin
A10: G0028 | B10: 1004 | C10: 45523 | E10: =VLOOKUP(A10,Geraete!A:F,2,FALSE) -> Beamer | F10: =VLOOKUP(A10,Geraete!A:F,3,FALSE) -> Epson EB | G10: =VLOOKUP(A10,Geraete!A:F,4,FALSE) -> 44945 | H10: =VLOOKUP(A10,Geraete!A:F,5,FALSE) -> 1246.58 | I10: =VLOOKUP(A10,Geraete!A:F,6,FALSE) -> Hamburg | J10: =VLOOKUP(B10&"",Mitarbeiter!$A:$D,2,FALSE) -> Klemens Löffler | K10: =VLOOKUP(B10&"",Mitarbeiter!$A:$D,3,FALSE) -> Vertrieb | L10: =VLOOKUP(B10&"",Mitarbeiter!$A:$D,4,FALSE) -> Hamburg
A11: G0013 | B11: 1012 | C11: 45419 | D11: 45470 | E11: =VLOOKUP(A11,Geraete!A:F,2,FALSE) -> Drucker | F11: =VLOOKUP(A11,Geraete!A:F,3,FALSE) -> Canon Pixma | G11: =VLOOKUP(A11,Geraete!A:F,4,FALSE) -> 44332 | H11: =VLOOKUP(A11,Geraete!A:F,5,FALSE) -> 1898.65 | I11: =VLOOKUP(A11,Geraete!A:F,6,FALSE) -> Hamburg | J11: =VLOOKUP(B11&"",Mitarbeiter!$A:$D,2,FALSE) -> Ariane Klemt-Kaul | K11: =VLOOKUP(B11&"",Mitarbeiter!$A:$D,3,FALSE) -> IT | L11: =VLOOKUP(B11&"",Mitarbeiter!$A:$D,4,FALSE) -> München
A12: G0024 | B12: 1008 | C12: 45375 | E12: =VLOOKUP(A12,Geraete!A:F,2,FALSE) -> Monitor | F12: =VLOOKUP(A12,Geraete!A:F,3,FALSE) -> Dell UltraSharp | G12: =VLOOKUP(A12,Geraete!A:F,4,FALSE) -> 44621 | H12: =VLOOKUP(A12,Geraete!A:F,5,FALSE) -> 750.91 | I12: =VLOOKUP(A12,Geraete!A:F,6,FALSE) -> Berlin | J12: =VLOOKUP(B12&"",Mitarbeiter!$A:$D,2,FALSE) -> Dipl.-Ing. Klaus-Werner Holsten B.Sc. | K12: =VLOOKUP(B12&"",Mitarbeiter!$A:$D,3,FALSE) -> IT | L12: =VLOOKUP(B12&"",Mitarbeiter!$A:$D,4,FALSE) -> Hamburg
A13: G0029 | B13: 1002 | C13: 45921 | D13: 45934 | E13: =VLOOKUP(A13,Geraete!A:F,2,FALSE) -> Laptop | F13: =VLOOKUP(A13,Geraete!A:F,3,FALSE) -> Lenovo ThinkPad | G13: =VLOOKUP(A13,Geraete!A:F,4,FALSE) -> 44337 | H13: =VLOOKUP(A13,Geraete!A:F,5,FALSE) -> 1553.15 | I13: =VLOOKUP(A13,Geraete!A:F,6,FALSE) -> Hamburg | J13: =VLOOKUP(B13&"",Mitarbeiter!$A:$D,2,FALSE) -> Eleni Hauffer | K13: =VLOOKUP(B13&"",Mitarbeiter!$A:$D,3,FALSE) -> IT | L13: =VLOOKUP(B13&"",Mitarbeiter!$A:$D,4,FALSE) -> Berlin
A14: G0005 | B14: 1006 | C14: 45892 | D14: 45922 | E14: =VLOOKUP(A14,Geraete!A:F,2,FALSE) -> Drucker | F14: =VLOOKUP(A14,Geraete!A:F,3,FALSE) -> Canon Pixma | G14: =VLOOKUP(A14,Geraete!A:F,4,FALSE) -> 44503 | H14: =VLOOKUP(A14,Geraete!A:F,5,FALSE) -> 823.23 | I14: =VLOOKUP(A14,Geraete!A:F,6,FALSE) -> Berlin | J14: =VLOOKUP(B14&"",Mitarbeiter!$A:$D,2,FALSE) -> Eric Patberg B.Sc. | K14: =VLOOKUP(B14&"",Mitarbeiter!$A:$D,3,FALSE) -> Vertrieb | L14: =VLOOKUP(B14&"",Mitarbeiter!$A:$D,4,FALSE) -> Hamburg
A15: G0015 | B15: 1010 | C15: 45377 | D15: 45886 | E15: =VLOOKUP(A15,Geraete!A:F,2,FALSE) -> Smartphone | F15: =VLOOKUP(A15,Geraete!A:F,3,FALSE) -> iPhone 13 | G15: =VLOOKUP(A15,Geraete!A:F,4,FALSE) -> 44824 | H15: =VLOOKUP(A15,Geraete!A:F,5,FALSE) -> 661.44 | I15: =VLOOKUP(A15,Geraete!A:F,6,FALSE) -> München | J15: =VLOOKUP(B15&"",Mitarbeiter!$A:$D,2,FALSE) -> Carolin Hande | K15: =VLOOKUP(B15&"",Mitarbeiter!$A:$D,3,FALSE) -> IT | L15: =VLOOKUP(B15&"",Mitarbeiter!$A:$D,4,FALSE) -> Hamburg
A16: G0005 | B16: 1012 | C16: 45599 | E16: =VLOOKUP(A16,Geraete!A:F,2,FALSE) -> Drucker | F16: =VLOOKUP(A16,Geraete!A:F,3,FALSE) -> Canon Pixma | G16: =VLOOKUP(A16,Geraete!A:F,4,FALSE) -> 44503 | H16: =VLOOKUP(A16,Geraete!A:F,5,FALSE) -> 823.23 | I16: =VLOOKUP(A16,Geraete!A:F,6,FALSE) -> Berlin | J16: =VLOOKUP(B16&"",Mitarbeiter!$A:$D,2,FALSE) -> Ariane Klemt-Kaul | K16: =VLOOKUP(B16&"",Mitarbeiter!$A:$D,3,FALSE) -> IT | L16: =VLOOKUP(B16&"",Mitarbeiter!$A:$D,4,FALSE) -> München
A17: G0015 | B17: 1002 | C17: 45519 | E17: =VLOOKUP(A17,Geraete!A:F,2,FALSE) -> Smartphone | F17: =VLOOKUP(A17,Geraete!A:F,3,FALSE) -> iPhone 13 | G17: =VLOOKUP(A17,Geraete!A:F,4,FALSE) -> 44824 | H17: =VLOOKUP(A17,Geraete!A:F,5,FALSE) -> 661.44 | I17: =VLOOKUP(A17,Geraete!A:F,6,FALSE) -> München | J17: =VLOOKUP(B17&"",Mitarbeiter!$A:$D,2,FALSE) -> Eleni Hauffer | K17: =VLOOKUP(B17&"",Mitarbeiter!$A:$D,3,FALSE) -> IT | L17: =VLOOKUP(B17&"",Mitarbeiter!$A:$D,4,FALSE) -> Berlin
A18: G0022 | B18: 1002 | C18: 45899 | D18: 45930 | E18: =VLOOKUP(A18,Geraete!A:F,2,FALSE) -> Tablet | F18: =VLOOKUP(A18,Geraete!A:F,3,FALSE) -> iPad | G18: =VLOOKUP(A18,Geraete!A:F,4,FALSE) -> 45524 | H18: =VLOOKUP(A18,Geraete!A:F,5,FALSE) -> 1591.98 | I18: =VLOOKUP(A18,Geraete!A:F,6,FALSE) -> Hamburg | J18: =VLOOKUP(B18&"",Mitarbeiter!$A:$D,2,FALSE) -> Eleni Hauffer | K18: =VLOOKUP(B18&"",Mitarbeiter!$A:$D,3,FALSE) -> IT | L18: =VLOOKUP(B18&"",Mitarbeiter!$A:$D,4,FALSE) -> Berlin
A19: G0018 | B19: 1011 | C19: 45568 | D19: 45623 | E19: =VLOOKUP(A19,Geraete!A:F,2,FALSE) -> Tablet | F19: =VLOOKUP(A19,Geraete!A:F,3,FALSE) -> iPad | G19: =VLOOKUP(A19,Geraete!A:F,4,FALSE) -> 44839 | H19: =VLOOKUP(A19,Geraete!A:F,5,FALSE) -> 1688.07 | I19: =VLOOKUP(A19,Geraete!A:F,6,FALSE) -> München | J19: =VLOOKUP(B19&"",Mitarbeiter!$A:$D,2,FALSE) -> Auguste Davids | K19: =VLOOKUP(B19&"",Mitarbeiter!$A:$D,3,FALSE) -> IT | L19: =VLOOKUP(B19&"",Mitarbeiter!$A:$D,4,FALSE) -> Hamburg
A20: G0035 | B20: 1003 | C20: 45417 | E20: =VLOOKUP(A20,Geraete!A:F,2,FALSE) -> Beamer | F20: =VLOOKUP(A20,Geraete!A:F,3,FALSE) -> BenQ MW550 | G20: =VLOOKUP(A20,Geraete!A:F,4,FALSE) -> 45294 | H20: =VLOOKUP(A20,Geraete!A:F,5,FALSE) -> 644.54 | I20: =VLOOKUP(A20,Geraete!A:F,6,FALSE) -> Berlin | J20: =VLOOKUP(B20&"",Mitarbeiter!$A:$D,2,FALSE) -> Paul Dobes-Stiffel | K20: =VLOOKUP(B20&"",Mitarbeiter!$A:$D,3,FALSE) -> Produktion | L20: =VLOOKUP(B20&"",Mitarbeiter!$A:$D,4,FALSE) -> Hamburg
A21: G0031 | B21: 1004 | C21: 45320 | E21: =VLOOKUP(A21,Geraete!A:F,2,FALSE) -> Laptop | F21: =VLOOKUP(A21,Geraete!A:F,3,FALSE) -> HP EliteBook | G21: =VLOOKUP(A21,Geraete!A:F,4,FALSE) -> 45775 | H21: =VLOOKUP(A21,Geraete!A:F,5,FALSE) -> 1095.62 | I21: =VLOOKUP(A21,Geraete!A:F,6,FALSE) -> München | J21: =VLOOKUP(B21&"",Mitarbeiter!$A:$D,2,FALSE) -> Klemens Löffler | K21: =VLOOKUP(B21&"",Mitarbeiter!$A:$D,3,FALSE) -> Vertrieb | L21: =VLOOKUP(B21&"",Mitarbeiter!$A:$D,4,FALSE) -> Hamburg
A22: G0027 | B22: 1004 | C22: 45403 | D22: 45839 | E22: =VLOOKUP(A22,Geraete!A:F,2,FALSE) -> Monitor | F22: =VLOOKUP(A22,Geraete!A:F,3,FALSE) -> Samsung Curved | G22: =VLOOKUP(A22,Geraete!A:F,4,FALSE) -> 44766 | H22: =VLOOKUP(A22,Geraete!A:F,5,FALSE) -> 501.64 | I22: =VLOOKUP(A22,Geraete!A:F,6,FALSE) -> München | J22: =VLOOKUP(B22&"",Mitarbeiter!$A:$D,2,FALSE) -> Klemens Löffler | K22: =VLOOKUP(B22&"",Mitarbeiter!$A:$D,3,FALSE) -> Vertrieb | L22: =VLOOKUP(B22&"",Mitarbeiter!$A:$D,4,FALSE) -> Hamburg
A23: G0028 | B23: 1006 | C23: 45630 | D23: 45732 | E23: =VLOOKUP(A23,Geraete!A:F,2,FALSE) -> Beamer | F23: =VLOOKUP(A23,Geraete!A:F,3,FALSE) -> Epson EB | G23: =VLOOKUP(A23,Geraete!A:F,4,FALSE) -> 44945 | H23: =VLOOKUP(A23,Geraete!A:F,5,FALSE) -> 1246.58 | I23: =VLOOKUP(A23,Geraete!A:F,6,FALSE) -> Hamburg | J23: =VLOOKUP(B23&"",Mitarbeiter!$A:$D,2,FALSE) -> Eric Patberg B.Sc. | K23: =VLOOKUP(B23&"",Mitarbeiter!$A:$D,3,FALSE) -> Vertrieb | L23: =VLOOKUP(B23&"",Mitarbeiter!$A:$D,4,FALSE) -> Hamburg
A24: G0030 | B24: 1012 | C24: 45792 | D24: 45905 | E24: =VLOOKUP(A24,Geraete!A:F,2,FALSE) -> Beamer | F24: =VLOOKUP(A24,Geraete!A:F,3,FALSE) -> Epson EB | G24: =VLOOKUP(A24,Geraete!A:F,4,FALSE) -> 44647 | H24: =VLOOKUP(A24,Geraete!A:F,5,FALSE) -> 1629.76 | I24: =VLOOKUP(A24,Geraete!A:F,6,FALSE) -> München | J24: =VLOOKUP(B24&"",Mitarbeiter!$A:$D,2,FALSE) -> Ariane Klemt-Kaul | K24: =VLOOKUP(B24&"",Mitarbeiter!$A:$D,3,FALSE) -> IT | L24: =VLOOKUP(B24&"",Mitarbeiter!$A:$D,4,FALSE) -> München
A25: G0007 | B25: 1001 | C25: 45544 | D25: 45854 | E25: =VLOOKUP(A25,Geraete!A:F,2,FALSE) -> Laptop | F25: =VLOOKUP(A25,Geraete!A:F,3,FALSE) -> Lenovo ThinkPad | G25: =VLOOKUP(A25,Geraete!A:F,4,FALSE) -> 44360 | H25: =VLOOKUP(A25,Geraete!A:F,5,FALSE) -> 869.09 | I25: =VLOOKUP(A25,Geraete!A:F,6,FALSE) -> Hamburg | J25: =VLOOKUP(B25&"",Mitarbeiter!$A:$D,2,FALSE) -> Aleksandr Weinhage | K25: =VLOOKUP(B25&"",Mitarbeiter!$A:$D,3,FALSE) -> IT | L25: =VLOOKUP(B25&"",Mitarbeiter!$A:$D,4,FALSE) -> Berlin
A26: G0022 | B26: 1002 | C26: 45493 | D26: 45663 | E26: =VLOOKUP(A26,Geraete!A:F,2,FALSE) -> Tablet | F26: =VLOOKUP(A26,Geraete!A:F,3,FALSE) -> iPad | G26: =VLOOKUP(A26,Geraete!A:F,4,FALSE) -> 45524 | H26: =VLOOKUP(A26,Geraete!A:F,5,FALSE) -> 1591.98 | I26: =VLOOKUP(A26,Geraete!A:F,6,FALSE) -> Hamburg | J26: =VLOOKUP(B26&"",Mitarbeiter!$A:$D,2,FALSE) -> Eleni Hauffer | K26: =VLOOKUP(B26&"",Mitarbeiter!$A:$D,3,FALSE) -> IT | L26: =VLOOKUP(B26&"",Mitarbeiter!$A:$D,4,FALSE) -> Berlin
A27: G0013 | B27: 1009 | C27: 45319 | D27: 45714 | E27: =VLOOKUP(A27,Geraete!A:F,2,FALSE) -> Drucker | F27: =VLOOKUP(A27,Geraete!A:F,3,FALSE) -> Canon Pixma | G27: =VLOOKUP(A27,Geraete!A:F,4,FALSE) -> 44332 | H27: =VLOOKUP(A27,Geraete!A:F,5,FALSE) -> 1898.65 | I27: =VLOOKUP(A27,Geraete!A:F,6,FALSE) -> Hamburg | J27: =VLOOKUP(B27&"",Mitarbeiter!$A:$D,2,FALSE) -> Univ.Prof. Heimo Karge | K27: =VLOOKUP(B27&"",Mitarbeiter!$A:$D,3,FALSE) -> Marketing | L27: =VLOOKUP(B27&"",Mitarbeiter!$A:$D,4,FALSE) -> Hamburg
A28: G0028 | B28: 1003 | C28: 45595 | D28: 45630 | E28: =VLOOKUP(A28,Geraete!A:F,2,FALSE) -> Beamer | F28: =VLOOKUP(A28,Geraete!A:F,3,FALSE) -> Epson EB | G28: =VLOOKUP(A28,Geraete!A:F,4,FALSE) -> 44945 | H28: =VLOOKUP(A28,Geraete!A:F,5,FALSE) -> 1246.58 | I28: =VLOOKUP(A28,Geraete!A:F,6,FALSE) -> Hamburg | J28: =VLOOKUP(B28&"",Mitarbeiter!$A:$D,2,FALSE) -> Paul Dobes-Stiffel | K28: =VLOOKUP(B28&"",Mitarbeiter!$A:$D,3,FALSE) -> Produktion | L28: =VLOOKUP(B28&"",Mitarbeiter!$A:$D,4,FALSE) -> Hamburg
A29: G0016 | B29: 1002 | C29: 45799 | D29: 45808 | E29: =VLOOKUP(A29,Geraete!A:F,2,FALSE) -> Drucker | F29: =VLOOKUP(A29,Geraete!A:F,3,FALSE) -> Canon Pixma | G29: =VLOOKUP(A29,Geraete!A:F,4,FALSE) -> 45015 | H29: =VLOOKUP(A29,Geraete!A:F,5,FALSE) -> 1501.06 | I29: =VLOOKUP(A29,Geraete!A:F,6,FALSE) -> Berlin | J29: =VLOOKUP(B29&"",Mitarbeiter!$A:$D,2,FALSE) -> Eleni Hauffer | K29: =VLOOKUP(B29&"",Mitarbeiter!$A:$D,3,FALSE) -> IT | L29: =VLOOKUP(B29&"",Mitarbeiter!$A:$D,4,FALSE) -> Berlin
A30: G0007 | B30: 1001 | C30: 45880 | E30: =VLOOKUP(A30,Geraete!A:F,2,FALSE) -> Laptop | F30: =VLOOKUP(A30,Geraete!A:F,3,FALSE) -> Lenovo ThinkPad | G30: =VLOOKUP(A30,Geraete!A:F,4,FALSE) -> 44360 | H30: =VLOOKUP(A30,Geraete!A:F,5,FALSE) -> 869.09 | I30: =VLOOKUP(A30,Geraete!A:F,6,FALSE) -> Hamburg | J30: =VLOOKUP(B30&"",Mitarbeiter!$A:$D,2,FALSE) -> Aleksandr Weinhage | K30: =VLOOKUP(B30&"",Mitarbeiter!$A:$D,3,FALSE) -> IT | L30: =VLOOKUP(B30&"",Mitarbeiter!$A:$D,4,FALSE) -> Berlin
A31: G0035 | B31: 1001 | C31: 45297 | E31: =VLOOKUP(A31,Geraete!A:F,2,FALSE) -> Beamer | F31: =VLOOKUP(A31,Geraete!A:F,3,FALSE) -> BenQ MW550 | G31: =VLOOKUP(A31,Geraete!A:F,4,FALSE) -> 45294 | H31: =VLOOKUP(A31,Geraete!A:F,5,FALSE) -> 644.54 | I31: =VLOOKUP(A31,Geraete!A:F,6,FALSE) -> Berlin | J31: =VLOOKUP(B31&"",Mitarbeiter!$A:$D,2,FALSE) -> Aleksandr Weinhage | K31: =VLOOKUP(B31&"",Mitarbeiter!$A:$D,3,FALSE) -> IT | L31: =VLOOKUP(B31&"",Mitarbeiter!$A:$D,4,FALSE) -> Berlin
A32: G0016 | B32: 1003 | C32: 45330 | D32: 45817 | E32: =VLOOKUP(A32,Geraete!A:F,2,FALSE) -> Drucker | F32: =VLOOKUP(A32,Geraete!A:F,3,FALSE) -> Canon Pixma | G32: =VLOOKUP(A32,Geraete!A:F,4,FALSE) -> 45015 | H32: =VLOOKUP(A32,Geraete!A:F,5,FALSE) -> 1501.06 | I32: =VLOOKUP(A32,Geraete!A:F,6,FALSE) -> Berlin | J32: =VLOOKUP(B32&"",Mitarbeiter!$A:$D,2,FALSE) -> Paul Dobes-Stiffel | K32: =VLOOKUP(B32&"",Mitarbeiter!$A:$D,3,FALSE) -> Produktion | L32: =VLOOKUP(B32&"",Mitarbeiter!$A:$D,4,FALSE) -> Hamburg
A33: G0031 | B33: 1004 | C33: 45336 | E33: =VLOOKUP(A33,Geraete!A:F,2,FALSE) -> Laptop | F33: =VLOOKUP(A33,Geraete!A:F,3,FALSE) -> HP EliteBook | G33: =VLOOKUP(A33,Geraete!A:F,4,FALSE) -> 45775 | H33: =VLOOKUP(A33,Geraete!A:F,5,FALSE) -> 1095.62 | I33: =VLOOKUP(A33,Geraete!A:F,6,FALSE) -> München | J33: =VLOOKUP(B33&"",Mitarbeiter!$A:$D,2,FALSE) -> Klemens Löffler | K33: =VLOOKUP(B33&"",Mitarbeiter!$A:$D,3,FALSE) -> Vertrieb | L33: =VLOOKUP(B33&"",Mitarbeiter!$A:$D,4,FALSE) -> Hamburg
A34: G0004 | B34: 1003 | C34: 45827 | D34: 45908 | E34: =VLOOKUP(A34,Geraete!A:F,2,FALSE) -> Laptop | F34: =VLOOKUP(A34,Geraete!A:F,3,FALSE) -> Dell XPS | G34: =VLOOKUP(A34,Geraete!A:F,4,FALSE) -> 45782 | H34: =VLOOKUP(A34,Geraete!A:F,5,FALSE) -> 1007.88 | I34: =VLOOKUP(A34,Geraete!A:F,6,FALSE) -> München | J34: =VLOOKUP(B34&"",Mitarbeiter!$A:$D,2,FALSE) -> Paul Dobes-Stiffel | K34: =VLOOKUP(B34&"",Mitarbeiter!$A:$D,3,FALSE) -> Produktion | L34: =VLOOKUP(B34&"",Mitarbeiter!$A:$D,4,FALSE) -> Hamburg
A35: G0025 | B35: 1005 | C35: 45675 | E35: =VLOOKUP(A35,Geraete!A:F,2,FALSE) -> Beamer | F35: =VLOOKUP(A35,Geraete!A:F,3,FALSE) -> Epson EB | G35: =VLOOKUP(A35,Geraete!A:F,4,FALSE) -> 45266 | H35: =VLOOKUP(A35,Geraete!A:F,5,FALSE) -> 545.46 | I35: =VLOOKUP(A35,Geraete!A:F,6,FALSE) -> Berlin | J35: =VLOOKUP(B35&"",Mitarbeiter!$A:$D,2,FALSE) -> Alexandre Davids | K35: =VLOOKUP(B35&"",Mitarbeiter!$A:$D,3,FALSE) -> Vertrieb | L35: =VLOOKUP(B35&"",Mitarbeiter!$A:$D,4,FALSE) -> Berlin
A36: G0030 | B36: 1005 | C36: 45261 | D36: 45559 | E36: =VLOOKUP(A36,Geraete!A:F,2,FALSE) -> Beamer | F36: =VLOOKUP(A36,Geraete!A:F,3,FALSE) -> Epson EB | G36: =VLOOKUP(A36,Geraete!A:F,4,FALSE) -> 44647 | H36: =VLOOKUP(A36,Geraete!A:F,5,FALSE) -> 1629.76 | I36: =VLOOKUP(A36,Geraete!A:F,6,FALSE) -> München | J36: =VLOOKUP(B36&"",Mitarbeiter!$A:$D,2,FALSE) -> Alexandre Davids | K36: =VLOOKUP(B36&"",Mitarbeiter!$A:$D,3,FALSE) -> Vertrieb | L36: =VLOOKUP(B36&"",Mitarbeiter!$A:$D,4,FALSE) -> Berlin
A37: G0032 | B37: 1003 | C37: 45508 | D37: 45871 | E37: =VLOOKUP(A37,Geraete!A:F,2,FALSE) -> Laptop | F37: =VLOOKUP(A37,Geraete!A:F,3,FALSE) -> Lenovo ThinkPad | G37: =VLOOKUP(A37,Geraete!A:F,4,FALSE) -> 44876 | H37: =VLOOKUP(A37,Geraete!A:F,5,FALSE) -> 1801.36 | I37: =VLOOKUP(A37,Geraete!A:F,6,FALSE) -> München | J37: =VLOOKUP(B37&"",Mitarbeiter!$A:$D,2,FALSE) -> Paul Dobes-Stiffel | K37: =VLOOKUP(B37&"",Mitarbeiter!$A:$D,3,FALSE) -> Produktion | L37: =VLOOKUP(B37&"",Mitarbeiter!$A:$D,4,FALSE) -> Hamburg
A38: G0014 | B38: 1001 | C38: 45622 | D38: 45719 | E38: =VLOOKUP(A38,Geraete!A:F,2,FALSE) -> Laptop | F38: =VLOOKUP(A38,Geraete!A:F,3,FALSE) -> Lenovo ThinkPad | G38: =VLOOKUP(A38,Geraete!A:F,4,FALSE) -> 44258 | H38: =VLOOKUP(A38,Geraete!A:F,5,FALSE) -> 1415.97 | I38: =VLOOKUP(A38,Geraete!A:F,6,FALSE) -> Hamburg | J38: =VLOOKUP(B38&"",Mitarbeiter!$A:$D,2,FALSE) -> Aleksandr Weinhage | K38: =VLOOKUP(B38&"",Mitarbeiter!$A:$D,3,FALSE) -> IT | L38: =VLOOKUP(B38&"",Mitarbeiter!$A:$D,4,FALSE) -> Berlin
A39: G0035 | B39: 1001 | C39: 45641 | E39: =VLOOKUP(A39,Geraete!A:F,2,FALSE) -> Beamer | F39: =VLOOKUP(A39,Geraete!A:F,3,FALSE) -> BenQ MW550 | G39: =VLOOKUP(A39,Geraete!A:F,4,FALSE) -> 45294 | H39: =VLOOKUP(A39,Geraete!A:F,5,FALSE) -> 644.54 | I39: =VLOOKUP(A39,Geraete!A:F,6,FALSE) -> Berlin | J39: =VLOOKUP(B39&"",Mitarbeiter!$A:$D,2,FALSE) -> Aleksandr Weinhage | K39: =VLOOKUP(B39&"",Mitarbeiter!$A:$D,3,FALSE) -> IT | L39: =VLOOKUP(B39&"",Mitarbeiter!$A:$D,4,FALSE) -> Berlin
A40: G0004 | B40: 1001 | C40: 45880 | D40: 45881 | E40: =VLOOKUP(A40,Geraete!A:F,2,FALSE) -> Laptop | F40: =VLOOKUP(A40,Geraete!A:F,3,FALSE) -> Dell XPS | G40: =VLOOKUP(A40,Geraete!A:F,4,FALSE) -> 45782 | H40: =VLOOKUP(A40,Geraete!A:F,5,FALSE) -> 1007.88 | I40: =VLOOKUP(A40,Geraete!A:F,6,FALSE) -> München | J40: =VLOOKUP(B40&"",Mitarbeiter!$A:$D,2,FALSE) -> Aleksandr Weinhage | K40: =VLOOKUP(B40&"",Mitarbeiter!$A:$D,3,FALSE) -> IT | L40: =VLOOKUP(B40&"",Mitarbeiter!$A:$D,4,FALSE) -> Berlin
...
